Traceback (most recent call last):
  File "C:\Users\jrf046\AppData\Local\Programs\Python\Python39\lib\site-packages\httpx\_transports\default.py", line 72, in map_httpcore_exceptions
    yield
  File "C:\Users\jrf046\AppData\Local\Programs\Python\Python39\lib\site-packages\httpx\_transports\default.py", line 236, in handle_request
    resp = self._pool.handle_request(req)
  File "C:\Users\jrf046\AppData\Local\Programs\Python\Python39\lib\site-packages\httpcore\_sync\connection_pool.py", line 216, in handle_request
    raise exc from None
  File "C:\Users\jrf046\AppData\Local\Programs\Python\Python39\lib\site-packages\httpcore\_sync\connection_pool.py", line 196, in handle_request
    response = connection.handle_request(
  File "C:\Users\jrf046\AppData\Local\Programs\Python\Python39\lib\site-packages\httpcore\_sync\http_proxy.py", line 289, in handle_request
    connect_response = self._connection.handle_request(
  File "C:\Users\jrf046\AppData\Local\Programs\Python\Python39\lib\site-packages\httpcore\_sync\connection.py", line 99, in handle_request
    raise exc
  File "C:\Users\jrf046\AppData\Local\Programs\Python\Python39\lib\site-packages\httpcore\_sync\connection.py", line 76, in handle_request
    stream = self._connect(request)
  File "C:\Users\jrf046\AppData\Local\Programs\Python\Python39\lib\site-packages\httpcore\_sync\connection.py", line 154, in _connect
    stream = stream.start_tls(**kwargs)
  File "C:\Users\jrf046\AppData\Local\Programs\Python\Python39\lib\site-packages\httpcore\_backends\sync.py", line 168, in start_tls
    raise exc
  File "C:\Users\jrf046\AppData\Local\Programs\Python\Python39\lib\contextlib.py", line 135, in __exit__
    self.gen.throw(type, value, traceback)
  File "C:\Users\jrf046\AppData\Local\Programs\Python\Python39\lib\site-packages\httpcore\_exceptions.py", line 14, in map_exceptions
    raise to_exc(exc) from exc
httpcore.ConnectError: [SSL: WRONG_VERSION_NUMBER] wrong version number (_ssl.c:1123)

The above exception was the direct cause of the following exception:

Traceback (most recent call last):
  File "C:\Hem's Documents\CM Reporting\CCR - Main\duty-executive\duty_exec.py", line 673, in <module>
    html_content = generate_html(
  File "C:\Hem's Documents\CM Reporting\CCR - Main\duty-executive\duty_exec.py", line 112, in generate_html
    from_date_fr = translate_to_french(from_date_en)
  File "C:\Hem's Documents\CM Reporting\CCR - Main\duty-executive\duty_exec.py", line 33, in translate_to_french
    translated_text = translator.translate(text, src='en', dest='fr')
  File "C:\Users\jrf046\AppData\Local\Programs\Python\Python39\lib\site-packages\googletrans\client.py", line 185, in translate
    data = self._translate(text, dest, src, kwargs)
  File "C:\Users\jrf046\AppData\Local\Programs\Python\Python39\lib\site-packages\googletrans\client.py", line 86, in _translate
    r = self.client.get(url, params=params)
  File "C:\Users\jrf046\AppData\Local\Programs\Python\Python39\lib\site-packages\httpx\_client.py", line 1066, in get
    return self.request(
  File "C:\Users\jrf046\AppData\Local\Programs\Python\Python39\lib\site-packages\httpx\_client.py", line 837, in request
    return self.send(request, auth=auth, follow_redirects=follow_redirects)
  File "C:\Users\jrf046\AppData\Local\Programs\Python\Python39\lib\site-packages\httpx\_client.py", line 926, in send
    response = self._send_handling_auth(
  File "C:\Users\jrf046\AppData\Local\Programs\Python\Python39\lib\site-packages\httpx\_client.py", line 954, in _send_handling_auth
    response = self._send_handling_redirects(
  File "C:\Users\jrf046\AppData\Local\Programs\Python\Python39\lib\site-packages\httpx\_client.py", line 991, in _send_handling_redirects
    response = self._send_single_request(request)
  File "C:\Users\jrf046\AppData\Local\Programs\Python\Python39\lib\site-packages\httpx\_client.py", line 1027, in _send_single_request
    response = transport.handle_request(request)
  File "C:\Users\jrf046\AppData\Local\Programs\Python\Python39\lib\site-packages\httpx\_transports\default.py", line 236, in handle_request
    resp = self._pool.handle_request(req)
  File "C:\Users\jrf046\AppData\Local\Programs\Python\Python39\lib\contextlib.py", line 135, in __exit__
    self.gen.throw(type, value, traceback)
  File "C:\Users\jrf046\AppData\Local\Programs\Python\Python39\lib\site-packages\httpx\_transports\default.py", line 89, in map_httpcore_exceptions
    raise mapped_exc(message) from exc
httpx.ConnectError: [SSL: WRONG_VERSION_NUMBER] wrong version number (_ssl.c:1123)
